<?xml version="1.0" ?>
<!-- =================================================================================== -->
<!-- |    This document was autogenerated by xacro from hopper.xacro                   | -->
<!-- |    EDITING THIS FILE BY HAND IS NOT RECOMMENDED                                 | -->
<!-- =================================================================================== -->
<robot name="Hopper">
  <material name="white">
    <color rgba="1 1 1 1"/>
  </material>
  <material name="red">
    <color rgba="1 0 0 1"/>
  </material>
  <!-- main body -->
  <link name="base_link"/>
  <link name="body_link">  
    <visual>
      <geometry>
        <mesh filename="package://urdf_tutorial/meshes/hopper_body.dae" scale="0.001 0.001 0.001"/>
      </geometry>
      <material name="white"/>
    </visual>
  </link>
  <joint name="base_joint" type="fixed">
    <parent link="base_link"/>
    <child link="body_link"/>
  </joint>
  <!-- <link name="base_stabilized"/>
    <joint name="base_orientation_joint" type="fixed">
        <parent link="base_stabilized" />
        <child link="base_link" />
    </joint> -->
  <!-- forward arrow -->
  <link name="arrow">
    <visual>
      <geometry>
        <cylinder length="0.2" radius="0.01"/>
      </geometry>
      <material name="red"/>
      <origin rpy="0 1.5707963267948966 0" xyz="0.1 0 0"/>
    </visual>
  </link>
  <joint name="arrow_joint" type="fixed">
    <parent link="base_link"/>
    <child link="arrow"/>
  </joint>
  <!-- laser attachment -->
  <link name="laser"/>
  <joint name="body_laser_joint" type="fixed">
    <parent link="body_link"/>
    <child link="laser"/>
    <origin rpy="0 0 3.141592653589793" xyz="0.035 0 0.112"/>
  </joint>
  <!-- IMU attachment -->
  <link name="imu"/>
  <joint name="body_imu_joint" type="fixed">
    <parent link="body_link"/>
    <child link="imu"/>
    <origin rpy="3.141592653589793 0 3.141592653589793" xyz="0.025 0 0"/>
  </joint>
  <!-- leg base -->
  <link name="right_rear_leg_base"/>
  <joint name="right_rear_leg_base_joint" type="fixed">
    <origin rpy="0.0 0.0 0.0" xyz="-0.115 -0.063 0.0"/>
    <parent link="body_link"/>
    <child link="right_rear_leg_base"/>
  </joint>
  <!-- coxa -->
  <link name="right_rear_coxa">
    <visual>
      <geometry>
        <mesh filename="package://urdf_tutorial/meshes/hopper_leg_coxa.dae" scale="0.001 0.001 0.001"/>
      </geometry>
      <material name="white"/>
    </visual>
  </link>
  <joint name="right_rear_coxa_joint" type="revolute">
    <origin rpy="0.0 0.0 -1.5707963267948966" xyz="0.0 0.0 0.0"/>
    <parent link="right_rear_leg_base"/>
    <child link="right_rear_coxa"/>
    <axis xyz="0.0 0.0 1.0"/>
    <limit effort="1000.0" lower="-3.141592653589793" upper="3.141592653589793" velocity="1"/>
  </joint>
  <!-- femur -->
  <link name="right_rear_femur">
    <visual>
      <geometry>
        <mesh filename="package://urdf_tutorial/meshes/hopper_leg_femur.dae" scale="0.001 0.001 0.001"/>
      </geometry>
      <material name="white"/>
    </visual>
  </link>
  <joint name="right_rear_femur_joint" type="revolute">
    <origin rpy="-1.5707963267948966 1.5707963267948966 0.0" xyz="0.044 0.0 0.0"/>
    <parent link="right_rear_coxa"/>
    <child link="right_rear_femur"/>
    <axis xyz="0.0 0.0 -1"/>
    <limit effort="1000.0" lower="-3.141592653589793" upper="3.141592653589793" velocity="1"/>
  </joint>
  <!-- tibia -->
  <link name="right_rear_tibia">
    <visual>
      <geometry>
        <mesh filename="package://urdf_tutorial/meshes/hopper_leg_tibia.dae" scale="0.001 0.001 0.001"/>
      </geometry>
      <material name="white"/>
    </visual>
  </link>
  <joint name="right_rear_tibia_joint" type="revolute">
    <origin rpy="3.141592653589793 0.0 0.0" xyz="0.0 -0.07 0.0"/>
    <parent link="right_rear_femur"/>
    <child link="right_rear_tibia"/>
    <axis xyz="0.0 0.0 1"/>
    <limit effort="1000.0" lower="-3.141592653589793" upper="3.141592653589793" velocity="1"/>
  </joint>
  <link name="right_rear_button"/>
  <joint name="right_rear_tibia_button" type="fixed">
    <origin xyz="0.128 0.0 0.0"/>
    <parent link="right_rear_tibia"/>
    <child link="right_rear_button"/>
  </joint>
  <!-- leg base -->
  <link name="right_middle_leg_base"/>
  <joint name="right_middle_leg_base_joint" type="fixed">
    <origin rpy="0.0 0.0 0.0" xyz="0.0 -0.103 0.0"/>
    <parent link="body_link"/>
    <child link="right_middle_leg_base"/>
  </joint>
  <!-- coxa -->
  <link name="right_middle_coxa">
    <visual>
      <geometry>
        <mesh filename="package://urdf_tutorial/meshes/hopper_leg_coxa.dae" scale="0.001 0.001 0.001"/>
      </geometry>
      <material name="white"/>
    </visual>
  </link>
  <joint name="right_middle_coxa_joint" type="revolute">
    <origin rpy="0.0 0.0 -1.5707963267948966" xyz="0.0 0.0 0.0"/>
    <parent link="right_middle_leg_base"/>
    <child link="right_middle_coxa"/>
    <axis xyz="0.0 0.0 1.0"/>
    <limit effort="1000.0" lower="-3.141592653589793" upper="3.141592653589793" velocity="1"/>
  </joint>
  <!-- femur -->
  <link name="right_middle_femur">
    <visual>
      <geometry>
        <mesh filename="package://urdf_tutorial/meshes/hopper_leg_femur.dae" scale="0.001 0.001 0.001"/>
      </geometry>
      <material name="white"/>
    </visual>
  </link>
  <joint name="right_middle_femur_joint" type="revolute">
    <origin rpy="-1.5707963267948966 1.5707963267948966 0.0" xyz="0.044 0.0 0.0"/>
    <parent link="right_middle_coxa"/>
    <child link="right_middle_femur"/>
    <axis xyz="0.0 0.0 -1"/>
    <limit effort="1000.0" lower="-3.141592653589793" upper="3.141592653589793" velocity="1"/>
  </joint>
  <!-- tibia -->
  <link name="right_middle_tibia">
    <visual>
      <geometry>
        <mesh filename="package://urdf_tutorial/meshes/hopper_leg_tibia.dae" scale="0.001 0.001 0.001"/>
      </geometry>
      <material name="white"/>
    </visual>
  </link>
  <joint name="right_middle_tibia_joint" type="revolute">
    <origin rpy="3.141592653589793 0.0 0.0" xyz="0.0 -0.07 0.0"/>
    <parent link="right_middle_femur"/>
    <child link="right_middle_tibia"/>
    <axis xyz="0.0 0.0 1"/>
    <limit effort="1000.0" lower="-3.141592653589793" upper="3.141592653589793" velocity="1"/>
  </joint>
  <link name="right_middle_button"/>
  <joint name="right_middle_tibia_button" type="fixed">
    <origin xyz="0.128 0.0 0.0"/>
    <parent link="right_middle_tibia"/>
    <child link="right_middle_button"/>
  </joint>
  <!-- leg base -->
  <link name="right_front_leg_base"/>
  <joint name="right_front_leg_base_joint" type="fixed">
    <origin rpy="0.0 0.0 0.0" xyz="0.115 -0.063 0.0"/>
    <parent link="body_link"/>
    <child link="right_front_leg_base"/>
  </joint>
  <!-- coxa -->
  <link name="right_front_coxa">
    <visual>
      <geometry>
        <mesh filename="package://urdf_tutorial/meshes/hopper_leg_coxa.dae" scale="0.001 0.001 0.001"/>
      </geometry>
      <material name="white"/>
    </visual>
  </link>
  <joint name="right_front_coxa_joint" type="revolute">
    <origin rpy="0.0 0.0 -1.5707963267948966" xyz="0.0 0.0 0.0"/>
    <parent link="right_front_leg_base"/>
    <child link="right_front_coxa"/>
    <axis xyz="0.0 0.0 1.0"/>
    <limit effort="1000.0" lower="-3.141592653589793" upper="3.141592653589793" velocity="1"/>
  </joint>
  <!-- femur -->
  <link name="right_front_femur">
    <visual>
      <geometry>
        <mesh filename="package://urdf_tutorial/meshes/hopper_leg_femur.dae" scale="0.001 0.001 0.001"/>
      </geometry>
      <material name="white"/>
    </visual>
  </link>
  <joint name="right_front_femur_joint" type="revolute">
    <origin rpy="-1.5707963267948966 1.5707963267948966 0.0" xyz="0.044 0.0 0.0"/>
    <parent link="right_front_coxa"/>
    <child link="right_front_femur"/>
    <axis xyz="0.0 0.0 -1"/>
    <limit effort="1000.0" lower="-3.141592653589793" upper="3.141592653589793" velocity="1"/>
  </joint>
  <!-- tibia -->
  <link name="right_front_tibia">
    <visual>
      <geometry>
        <mesh filename="package://urdf_tutorial/meshes/hopper_leg_tibia.dae" scale="0.001 0.001 0.001"/>
      </geometry>
      <material name="white"/>
    </visual>
  </link>
  <joint name="right_front_tibia_joint" type="revolute">
    <origin rpy="3.141592653589793 0.0 0.0" xyz="0.0 -0.07 0.0"/>
    <parent link="right_front_femur"/>
    <child link="right_front_tibia"/>
    <axis xyz="0.0 0.0 1"/>
    <limit effort="1000.0" lower="-3.141592653589793" upper="3.141592653589793" velocity="1"/>
  </joint>
  <link name="right_front_button"/>
  <joint name="right_front_tibia_button" type="fixed">
    <origin xyz="0.128 0.0 0.0"/>
    <parent link="right_front_tibia"/>
    <child link="right_front_button"/>
  </joint>
  <!-- leg base -->
  <link name="left_rear_leg_base"/>
  <joint name="left_rear_leg_base_joint" type="fixed">
    <origin rpy="0.0 0.0 0.0" xyz="-0.115 0.063 0.0"/>
    <parent link="body_link"/>
    <child link="left_rear_leg_base"/>
  </joint>
  <!-- coxa -->
  <link name="left_rear_coxa">
    <visual>
      <geometry>
        <mesh filename="package://urdf_tutorial/meshes/hopper_leg_coxa.dae" scale="0.001 0.001 0.001"/>
      </geometry>
      <material name="white"/>
    </visual>
  </link>
  <joint name="left_rear_coxa_joint" type="revolute">
    <origin rpy="0.0 0.0 1.5707963267948966" xyz="0.0 0.0 0.0"/>
    <parent link="left_rear_leg_base"/>
    <child link="left_rear_coxa"/>
    <axis xyz="0.0 0.0 1.0"/>
    <limit effort="1000.0" lower="-3.141592653589793" upper="3.141592653589793" velocity="1"/>
  </joint>
  <!-- femur -->
  <link name="left_rear_femur">
    <visual>
      <geometry>
        <mesh filename="package://urdf_tutorial/meshes/hopper_leg_femur.dae" scale="0.001 0.001 0.001"/>
      </geometry>
      <material name="white"/>
    </visual>
  </link>
  <joint name="left_rear_femur_joint" type="revolute">
    <origin rpy="-1.5707963267948966 1.5707963267948966 0.0" xyz="0.044 0.0 0.0"/>
    <parent link="left_rear_coxa"/>
    <child link="left_rear_femur"/>
    <axis xyz="0.0 0.0 1"/>
    <limit effort="1000.0" lower="-3.141592653589793" upper="3.141592653589793" velocity="1"/>
  </joint>
  <!-- tibia -->
  <link name="left_rear_tibia">
    <visual>
      <geometry>
        <mesh filename="package://urdf_tutorial/meshes/hopper_leg_tibia.dae" scale="0.001 0.001 0.001"/>
      </geometry>
      <material name="white"/>
    </visual>
  </link>
  <joint name="left_rear_tibia_joint" type="revolute">
    <origin rpy="3.141592653589793 0.0 0.0" xyz="0.0 -0.07 0.0"/>
    <parent link="left_rear_femur"/>
    <child link="left_rear_tibia"/>
    <axis xyz="0.0 0.0 -1"/>
    <limit effort="1000.0" lower="-3.141592653589793" upper="3.141592653589793" velocity="1"/>
  </joint>
  <link name="left_rear_button"/>
  <joint name="left_rear_tibia_button" type="fixed">
    <origin xyz="0.128 0.0 0.0"/>
    <parent link="left_rear_tibia"/>
    <child link="left_rear_button"/>
  </joint>
  <!-- leg base -->
  <link name="left_middle_leg_base"/>
  <joint name="left_middle_leg_base_joint" type="fixed">
    <origin rpy="0.0 0.0 0.0" xyz="0.0 0.103 0.0"/>
    <parent link="body_link"/>
    <child link="left_middle_leg_base"/>
  </joint>
  <!-- coxa -->
  <link name="left_middle_coxa">
    <visual>
      <geometry>
        <mesh filename="package://urdf_tutorial/meshes/hopper_leg_coxa.dae" scale="0.001 0.001 0.001"/>
      </geometry>
      <material name="white"/>
    </visual>
  </link>
  <joint name="left_middle_coxa_joint" type="revolute">
    <origin rpy="0.0 0.0 1.5707963267948966" xyz="0.0 0.0 0.0"/>
    <parent link="left_middle_leg_base"/>
    <child link="left_middle_coxa"/>
    <axis xyz="0.0 0.0 1.0"/>
    <limit effort="1000.0" lower="-3.141592653589793" upper="3.141592653589793" velocity="1"/>
  </joint>
  <!-- femur -->
  <link name="left_middle_femur">
    <visual>
      <geometry>
        <mesh filename="package://urdf_tutorial/meshes/hopper_leg_femur.dae" scale="0.001 0.001 0.001"/>
      </geometry>
      <material name="white"/>
    </visual>
  </link>
  <joint name="left_middle_femur_joint" type="revolute">
    <origin rpy="-1.5707963267948966 1.5707963267948966 0.0" xyz="0.044 0.0 0.0"/>
    <parent link="left_middle_coxa"/>
    <child link="left_middle_femur"/>
    <axis xyz="0.0 0.0 1"/>
    <limit effort="1000.0" lower="-3.141592653589793" upper="3.141592653589793" velocity="1"/>
  </joint>
  <!-- tibia -->
  <link name="left_middle_tibia">
    <visual>
      <geometry>
        <mesh filename="package://urdf_tutorial/meshes/hopper_leg_tibia.dae" scale="0.001 0.001 0.001"/>
      </geometry>
      <material name="white"/>
    </visual>
  </link>
  <joint name="left_middle_tibia_joint" type="revolute">
    <origin rpy="3.141592653589793 0.0 0.0" xyz="0.0 -0.07 0.0"/>
    <parent link="left_middle_femur"/>
    <child link="left_middle_tibia"/>
    <axis xyz="0.0 0.0 -1"/>
    <limit effort="1000.0" lower="-3.141592653589793" upper="3.141592653589793" velocity="1"/>
  </joint>
  <link name="left_middle_button"/>
  <joint name="left_middle_tibia_button" type="fixed">
    <origin xyz="0.128 0.0 0.0"/>
    <parent link="left_middle_tibia"/>
    <child link="left_middle_button"/>
  </joint>
  <!-- leg base -->
  <link name="left_front_leg_base"/>
  <joint name="left_front_leg_base_joint" type="fixed">
    <origin rpy="0.0 0.0 0.0" xyz="0.115 0.063 0.0"/>
    <parent link="body_link"/>
    <child link="left_front_leg_base"/>
  </joint>
  <!-- coxa -->
  <link name="left_front_coxa">
    <visual>
      <geometry>
        <mesh filename="package://urdf_tutorial/meshes/hopper_leg_coxa.dae" scale="0.001 0.001 0.001"/>
      </geometry>
      <material name="white"/>
    </visual>
  </link>
  <joint name="left_front_coxa_joint" type="revolute">
    <origin rpy="0.0 0.0 1.5707963267948966" xyz="0.0 0.0 0.0"/>
    <parent link="left_front_leg_base"/>
    <child link="left_front_coxa"/>
    <axis xyz="0.0 0.0 1.0"/>
    <limit effort="1000.0" lower="-3.141592653589793" upper="3.141592653589793" velocity="1"/>
  </joint>
  <!-- femur -->
  <link name="left_front_femur">
    <visual>
      <geometry>
        <mesh filename="package://urdf_tutorial/meshes/hopper_leg_femur.dae" scale="0.001 0.001 0.001"/>
      </geometry>
      <material name="white"/>
    </visual>
  </link>
  <joint name="left_front_femur_joint" type="revolute">
    <origin rpy="-1.5707963267948966 1.5707963267948966 0.0" xyz="0.044 0.0 0.0"/>
    <parent link="left_front_coxa"/>
    <child link="left_front_femur"/>
    <axis xyz="0.0 0.0 1"/>
    <limit effort="1000.0" lower="-3.141592653589793" upper="3.141592653589793" velocity="1"/>
  </joint>
  <!-- tibia -->
  <link name="left_front_tibia">
    <visual>
      <geometry>
        <mesh filename="package://urdf_tutorial/meshes/hopper_leg_tibia.dae" scale="0.001 0.001 0.001"/>
      </geometry>
      <material name="white"/>
    </visual>
  </link>
  <joint name="left_front_tibia_joint" type="revolute">
    <origin rpy="3.141592653589793 0.0 0.0" xyz="0.0 -0.07 0.0"/>
    <parent link="left_front_femur"/>
    <child link="left_front_tibia"/>
    <axis xyz="0.0 0.0 -1"/>
    <limit effort="1000.0" lower="-3.141592653589793" upper="3.141592653589793" velocity="1"/>
  </joint>
  <link name="left_front_button"/>
  <joint name="left_front_tibia_button" type="fixed">
    <origin xyz="0.128 0.0 0.0"/>
    <parent link="left_front_tibia"/>
    <child link="left_front_button"/>
  </joint>
</robot>
